Workbook

Sheet Assignment
E8: MBA
A10: COURSE : FINANCIAL MANAGEMENT (FM)
A12: GLOBAL CASE STUDY : FINANCIAL MODEL
A21: Assignment :
A22: You have just been hired as CFO by company defined in P2 History sheet. Your first assignment is to Value the company based on historical values and projected
A23: Cash Flows (CF's). To do this, your assignment is to create an excel financial model based on sheets P2 and P3 where you will have manually
A24: added figures/tables and based on sheets P4 to P9 where you will have to add the calculations in requested fields with formulas.
A25: Once completed all sheets from P1 to P9 you have to conclude based on obtained results : profitability of your investment, optimal capital structuire, Company value and associated risks
A26: Objective:
A27: The goal is to apply in practice the financial tools you have learned on FM lectures.
A28: It is a specific task whose solution makes it possible to understand and manage corporate finance in any company.
A30: Methodology :
A31: Before you start this assignment it is important that you complete all lectures and case studies in excel from course FM.
... A47: Good luck
A48: Instructor | C48: Summary
C49: P1 Tips'!A1
C50: P2 History'!A1
C51: P3 Inputs'!A1
C52: P4 Assets amortization'!A1
C53: P5 Cost of capital'!A1
C54: P6 P&L and BS Projection'!A1
C55: P7 CF''s projection'!A1
C56: P8 Scenarios'!A1
C57: P9 NWC'!A1
C58: P10 Valuation'!A1
C59: P11 Conclusion'!A1
C60: P12 Instructor'!A1

Sheet P1 Tips
D2: TIPS
B5: Total % in Assignment is 100%, while every sheet will be graded separately based on maximum points defined in each sheet.
B6: All sheets and cells have to be connected in a model using excel formulas
B7: Do calculations only in cells with blue color. Inputs are added manually in green color.
B8: You need a short Introduction in P2 History, short Explanations are to be added in cells for explanation in different sheets, and a short Conclusion in P10 sheet
B9: First projection year is N+1 (or Year 1) which is based on previous year N
B10: Year N (Year 0) is the last realized year in your P&L, Balance sheet and CF statement added in P2 sheet
B11: In P10 Conclusion sheet you are expected to give the answers :
D12: Whether your stocks are overvalued or undervalued ?
D13: Is IRR acceptable to Investors?
D14: How to increase the value of a company for owners ?
D15: Is the financing structure optimal?
B16: An additional plus is if you have good financial and adequate formulas in excel. In the model everything must be linked with formulas in excel such as (sum, if, NPV, IRR, PMT etc)
B17: If you use some external sources, especially in P2 and P3, you have to put data sources and to explain where have you found your datas and inputs
B20: Do not add manually figures in cells, except in P3 Inputs sheet
B21: Do not change the form or order of sheets
B22: Do not add lines or columns
B23: Do not copy paste data or form from preparatory case which has to be used only to help students to understand the Final Assignment.
B24: Do not stop if you can not complete one of the sheets. In such case you can continue on next sheet.
B25: If you need results from previous sheet and you have not been able to do previous sheet add figures manually in previous sheet even if you wil not get points for that.
B28: You can contact lecturer for any questions at the beginning, during or at the end of the Assignment

Sheet P2 History
B1: History of company | E1: Points | F1: 5
A3: Company | B3: Wipro Limited
A5: Logo
A11: Short History
B12: Founded by : | C12: Muhammed Hashim Premji
B13: Founded in year | C13: 29 December 1945, India
B14: Curent CEO | C14: Srini Pallia
B15: Main activities | C15: Wipro Limited is an Indian multinational technology company based in Bengaluru. It provides information technology, consulting and business process services, and is one of India's Big Six IT services companies.
B16: Other useful infos if necessary
O17: 1 | P17: 2 | Q17: 3
A18: Web Sources : | B18: https://www.wipro.com/
A20: Balance sheet | B20: Figures are in | C20: KUSD | J20: P&L | K20: Figures are in | L20: KUSD | T20: CF Statement | U20: Figures are in
E21: Year N | F21: Year N-1 | G21: Year N-2 | X21: Year N | Y21: Year N-1 | Z21: Year N-2
B22: Period Ending: | E22: 3/31/2026 | F22: 3/31/2025 | G22: 3/31/2024 | N22: Year N | O22: Year N-1 | P22: Year N-2 | T22: Period Ending: | X22: 3/31/2026 | Y22: 3/31/2025 | Z22: 3/31/2024
B23: Current Assets | K23: Period Ending: | N23: 3/31/2026 | O23: 3/31/2025 | P23: 3/31/2024 | T23: Net Income | X23: 1399000 | Y23: 1546000 | Z23: 1332000
B24: Cash and Cash Equivalents | E24: 1130000 | F24: 1469000 | G24: 1194000 | K24: Total Revenue | N24: 9765000 | O24: 10423000 | P24: 10762000 | T24: Cash Flows-Operating Activities
B25: Short-Term Investments | E25: 4615000 | F25: 4814000 | G25: 3731000 | K25: Cost of Revenue | N25: 6918000 | O25: 7228000 | P25: 7572000 | T25: Depreciation | X25: 307000 | Y25: 346000 | Z25: 409000
B26: Net Receivables | E26: 2243000 | F26: 2130000 | G26: 2084000 | K26: Gross Profit | N26: 2847000 | O26: 3195000 | P26: 3191000 | T26: Net Income Adjustments | X26: 292000 | Y26: 276000 | Z26: 347000
B27: Inventory | E27: 5000 | F27: 8000 | G27: 11000 | K27: Operating Expenses | T27: Changes in Operating Activities
B28: Other Current Assets | E28: 727000 | F28: 699000 | G28: 797000 | K28: Research and Development | N28: -- | O28: -- | P28: -- | T28: Accounts Receivable | X28: -274000 | Y28: 6000 | Z28: 165000
B29: Total Current Assets | E29: 8712000 | F29: 9100000 | G29: 7801000 | K29: Sales, General and Admin. | N29: 1272000 | O29: 1426000 | P29: 1563000 | T29: Changes in Inventories | X29: 2000 | Y29: 2000 | Z29: 3000
B30: Long-Term Assets | K30: Non-Recurring Items | N30: -- | O30: -- | P30: -- | T30: Other Operating Activities | X30: -2000 | Y30: 78000 | Z30: 107000
B31: Long-Term Investments | E31: 400000 | F31: 328000 | G31: 320000 | K31: Other Operating Items | N31: -- | O31: -- | P31: -- | T31: Liabilities | X31: -150000 | Y31: -272000 | Z31: -250000
B32: Fixed Assets | E32: 1160000 | F32: 1243000 | G32: 1193000 | K32: Operating Income | N32: 1575000 | O32: 1769000 | P32: 1628000 | T32: Net Cash Flow-Operating | X32: 1574000 | Y32: 1982000 | Z32: 2113000
B33: Goodwill | E33: 4084000 | F33: 3803000 | G33: 3789000 | K33: Add'l income/expense items | N33: 405000 | O33: 447000 | P33: 291000 | T33: Cash Flows-Investing Activities
B34: Intangible Assets | E34: 308000 | F34: 321000 | G34: 393000 | K34: Earnings Before Interest and Tax | N34: 1982000 | O34: 2220000 | P34: 1915000 | T34: Capital Expenditures | X34: -165000 | Y34: -172000 | Z34: -126000
B35: Other Assets | E35: 243000 | F35: 226000 | G35: 299000 | K35: Interest Expense | N35: 154000 | O35: 173000 | P35: 150000 | T35: Investments | X35: 78000 | Y35: -778000 | Z35: 278000
B36: Deferred Asset Charges | E36: 55000 | F36: 30000 | G36: 22000 | K36: Earnings Before Tax | N36: 1828000 | O36: 2047000 | P36: 1765000 | T36: Other Investing Activities | X36: -266000 | Y36: 6000 | Z36: -11000
B37: Total Assets | E37: 14963000 | F37: 15052000 | G37: 13818000 | K37: Income Tax | N37: 430000 | O37: 500000 | P37: 433000 | T37: Net Cash Flows-Investing | X37: -352000 | Y37: -945000 | Z37: 140000
B38: Current Liabilities | K38: Minority Interest | N38: 3000 | O38: 3000 | P38: -3000 | T38: Cash Flows-Financing Activities
B39: Accounts Payable | E39: 1524000 | F39: 1436000 | G39: 1323000 | K39: Equity Earnings/Loss Unconsolidated Subsidiary | N39: -- | O39: -- | P39: -- | T39: Sale and Purchase of Stock | X39: -- | Y39: -- | Z39: -1740000
B40: Short-Term Debt / Current Portion of Long-Term Debt | E40: 1865000 | F40: 1156000 | G40: 956000 | K40: Net Income-Cont. Operations | N40: 1401000 | O40: 1549000 | P40: 1330000 | T40: Net Borrowings | X40: -71000 | Y40: 210000 | Z40: -121000
B41: Other Current Liabilities | E41: 862000 | F41: 757000 | G41: 748000 | K41: Net Income | N41: 1399000 | O41: 1546000 | P41: 1332000 | T41: Other Financing Activities | X41: -198000 | Y41: -224000 | Z41: -262000
B42: Total Current Liabilities | E42: 4251000 | F42: 3349000 | G42: 3027000 | K42: Net Income Applicable to Common Shareholders | N42: 1399000 | O42: 1546000 | P42: 1332000 | T42: Net Cash Flows-Financing | X42: -1489000 | Y42: -748000 | Z42: -2189000
B43: Long-Term Debt | E43: 21000 | F43: 748000 | G43: 747000 | T43: Effect of Exchange Rate | X43: 94000 | Y43: 3000 | Z43: -3000
B44: Other Liabilities | E44: 1148000 | F44: 1047000 | G44: 828000 | T44: Net Cash Flow | X44: -267000 | Y44: 289000 | Z44: 64000
B45: Deferred Liability Charges | E45: 182000 | F45: 192000 | G45: 209000
B46: Misc. Stocks | E46: 26000 | F46: 25000 | G46: 16000
B47: Minority Interest | E47: -- | F47: -- | G47: --
B48: Total Liabilities | E48: 5628000 | F48: 5361000 | G48: 4827000
...

Sheet P3 Inputs
C1: Inputs of company
A2: (amounts in thousands)
B3: Year 0 | C3: Year 1 | D3: Year 2 | E3: Year 3 | F3: Year 4 | G3: Year 5 | H3: Year 6 | I3: Year 7
A4: Financial Plan
A5: Key Assumptions
A6: Sales increase/Decrease in % | C6: 0.25 | D6: 0.2 | E6: 0.1 | F6: 0.1 | G6: 0.1 | H6: 0.1 | I6: 0.1
A7: COGS increase/Decrease in % | B7: 0.5 | C7: 0.5 | D7: 0.5 | E7: 0.5 | F7: 0.5 | G7: 0.5 | H7: 0.5 | I7: 0.5
A8: Income tax in % | B8: 0.2 | C8: 0.2 | D8: 0.2 | E8: 0.2 | F8: 0.2 | G8: 0.2 | H8: 0.2 | I8: 0.2
A9: Interest rate Loan financing in % | B9: 0.077 | C9: 0.077 | D9: 0.077 | E9: 0.077 | F9: 0.077 | G9: 0.077 | H9: 0.077 | I9: 0.077
A10: Coupon rate Bond financing in % | B10: 0.05 | C10: 0.05 | D10: 0.05 | E10: 0.05 | F10: 0.05 | G10: 0.05 | H10: 0.05 | I10: 0.05
A11: Dividends Pay out ratio in % | B11: 0.5 | C11: 0.5 | D11: 0.5 | E11: 0.5 | F11: 0.5 | G11: 0.5 | H11: 0.5 | I11: 0.5
A12: Nmber of years of Capex project | B12: 7
A13: Growth rate of dividends forever | B13: 0.05
A14: Total Revenues in last realized year | B14: 6.73
A15: COGS in last realized year | B15: 4.45
A16: General and Administrative costs | C16: 0.05 | D16: 0.05 | E16: 0.05 | F16: 0.05 | G16: 0.05 | H16: 0.05 | I16: 0.05
A17: Net Income/Loss in last realized year | B17: ='P2 History'!N41 -> 1399000
A18: Current Stock price | B18: 2.39
A19: Current Number of stocks | B19: 10500000000
A20: New Capex as % of Total Revenues | B20: 0.1
A21: Cash balance in last realized year | B21: ='P2 History'!E24 -> 1130000
A22: Cash Increase/Decrease in % | C22: 0.1 | D22: 0.1 | E22: 0.1 | F22: 0.1 | G22: 0.1 | H22: 0.1 | I22: 0.1
A23: Receivables (% of sales) | C23: 0.15 | D23: 0.15 | E23: 0.15 | F23: 0.15 | G23: 0.15 | H23: 0.15 | I23: 0.15
A24: Stocks (% of COGS) | C24: 0.12 | D24: 0.12 | E24: 0.12 | F24: 0.12 | G24: 0.12 | H24: 0.12 | I24: 0.12
A25: Accumulated amortization in last realized year | B25: 312000
A26: Payables (% of COGS) | C26: 0.14 | D26: 0.14 | E26: 0.14 | F26: 0.14 | G26: 0.14 | H26: 0.14 | I26: 0.14
A27: Other liabilities (% of COGS) | C27: 0.02 | D27: 0.02 | E27: 0.02 | F27: 0.02 | G27: 0.02 | H27: 0.02 | I27: 0.02
A28: Shareholders Equity inlast realized year | B28: ='P2 History'!E55 -> 9335000
A29: Retained Earnings/Deferred Losses in last year
A30: Tangible (Net Fixed) Assets) in last year | B30: ='P2 History'!E32 -> 1160000
A31: Cash Flows resulting from new CAPEX in % | B31: 0.2 | C31: to be used in scenario analysis (P8)
A32: CAPEX increase in Worst case scenario 2 in % | B32: 0.2 | C32: to be used in scenario analysis (P8)
A33: CF's reduction in Worst case scenario 2 in % | B33: 0.05 | C33: to be used in scenario analysis (P8)
A34: CAPEX reduction in Best case scenario 3 in % | B34: 0.15 | C34: to be used in scenario analysis (P8)
A35: CF's increase in Best case scenario 3 in % | B35: 0.06 | C35: to be used in scenario analysis (P8)
A36: Growth rate of FCF forever | B36: 0.02

Sheet P4 Assets amortization
A1: Long Term Assets Depreciation/Amortization | F1: Points | G1: 5
A3: (amounts in thousands)
B4: Year 0 | C4: Year 1 | D4: Year 2 | E4: Year 3 | F4: Year 4 | G4: Year 5 | H4: Year 6 | I4: Year 7
A5: D&A of LT assets
A7: Existing annual D&A | B7: =('P2 History'!X25+'P2 History'!Y25+'P2 History'!Z25)/3 -> 354000 | C7: =B7 -> 354000 | D7: =C7 -> 354000 | E7: =D7 -> 354000 | F7: =E7 -> 354000 | G7: =F7 -> 354000 | H7: =G7 -> 354000 | I7: 0
A8: New Capex | B8: 0 | C8: ='P2 History'!N24*'P3 Inputs'!B20 -> 976500
A9: New CAPEX D&A | B9: 0 | C9: =C8/7 -> 139500 | D9: =C8/7 -> 139500 | E9: =C8/7 -> 139500 | F9: =C8/7 -> 139500 | G9: =C8/7 -> 139500 | H9: =C8/7 -> 139500 | I9: 0
A11: Total Assets D&A cost | B11: =B7+B9 -> 354000 | C11: =C7+C9 -> 493500 | D11: =D7+D9 -> 493500 | E11: =E7+E9 -> 493500 | F11: =F7+F9 -> 493500 | G11: =G7+G9 -> 493500 | H11: =H7+H9 -> 493500 | I11: =I7+I9 -> 0
A13: Cumulated Assets D&A cost | B13: =B11 -> 354000 | C13: =B13+C11 -> 847500 | D13: =C13+D11 -> 1341000 | E13: =D13+E11 -> 1834500 | F13: =E13+F11 -> 2328000 | G13: =F13+G11 -> 2821500 | H13: =G13+H11 -> 3315000 | I13: =H13+I11 -> 3315000
A19: Existing LT assets: carry forwarded the average depreciation from the last 3 realized years ($3,54,000 per year)
A20: New CAPEX: added a single CAPEX amount at the start of Year 1 (= beginning of Year N+1) equal to 10% of Total Revenue in Year N+1 ($9,76,500). In your table, New Capex appears only in Year 1.
A21: New CAPEX D&A: amortized that CAPEX using straight-line over 7 years, so New CAPEX D&A = $9,76,500 / 7 = $1,39,500 per year shown in Year 1 through Year 6, and 0 in Year 7.
A22: Total Assets D&A cost: each year’s total is simply Existing annual D&A + New CAPEX D&A.
A23: Cumulated Assets D&A cost: it’s the running total of Total Assets D&A cost across the years shown.

Sheet P5 Cost of capital
C1: Cost of Capital | F1: Points | G1: 15
A2: (amounts in thousands)
A3: LONG TERM FINANCING
A5: CAPEX | B5: ='P4 Assets amortization'!C8 -> 976500
A7: Bank Loan (5 points) | B7: =B5/3 -> 325500
A9: Interest rate / year | B9: ='P3 Inputs'!C9 -> 0.077
A10: Number of years | B10: ='P3 Inputs'!B12 -> 7
A12: Year | B12: Year 1 | C12: Year 2 | D12: Year 3 | E12: Year 4 | F12: Year 5 | G12: Year 6 | H12: Year 7
A13: Loan balance | B13: =B7 -> 325500 | C13: =B13-B16 -> 288683.94 | D13: =C13-C16 -> 249033.05 | E13: =D13-D16 -> 206329.04 | F13: =E13-E16 -> 160336.82 | G13: =F13-F16 -> 110803.2 | H13: =G13-G16 -> 57455.485 | I13: =H13-H16 -> -1.1641532e-10
A14: Payment-annuity | B14: =PMT(B9,B10,-B13,0,0) -> 61879.557 | C14: =PMT(B9,B10,-B13,0,0) -> 61879.557 | D14: =PMT(B9,B10,-B13,0,0) -> 61879.557 | E14: =PMT(B9,B10,-B13,0,0) -> 61879.557 | F14: =PMT(B9,B10,-B13,0,0) -> 61879.557 | G14: =PMT(B9,B10,-B13,0,0) -> 61879.557 | H14: =PMT(B9,B10,-B13,0,0) -> 61879.557 | I14: =PMT(B9,B10,-B13,0,0) -> 61879.557
A15: Interest value | B15: =B13*B9 -> 25063.5 | C15: =C13*B9 -> 22228.664 | D15: =D13*B9 -> 19175.545 | E15: =E13*B9 -> 15887.336 | F15: =F13*B9 -> 12345.935 | G15: =G13*B9 -> 8531.846 | H15: =H13*B9 -> 4424.0723 | I15: =B9*I13 -> -8.9639798e-12
A16: Principal value | B16: =B14-B15 -> 36816.057 | C16: =C14-C15 -> 39650.893 | D16: =D14-D15 -> 42704.012 | E16: =E14-E15 -> 45992.221 | F16: =F14-F15 -> 49533.622 | G16: =G14-G15 -> 53347.711 | H16: =H14-H15 -> 57455.485 | I16: =I14-I15 -> 61879.557
A19: Bonds (5 points) | B19: =B5/3 -> 325500
A20: Number of Periods to Maturity | B20: 7
A21: Face value | B21: =B5/3 -> 325500
A22: Coupon rate | B22: 0.05
A23: Coupon Payment | B23: =B21*B22 -> 16275
A25: Year | B25: Year 1 | C25: Year 2 | D25: Year 3 | E25: Year 4 | F25: Year 5 | G25: Year 6 | H25: Year 7
A26: Bond Balance | B26: =B21 -> 325500 | C26: =B21 -> 325500 | D26: =B21 -> 325500 | E26: =B21 -> 325500 | F26: =B21 -> 325500 | G26: =B21 -> 325500 | H26: =B21 -> 325500
A27: Coupons | B27: =B22*B26 -> 16275 | C27: =C26*B22 -> 16275 | D27: =D26*B22 -> 16275 | E27: =E26*B22 -> 16275 | F27: =F26*B22 -> 16275 | G27: =G26*B22 -> 16275 | H27: =H26*B22 -> 16275
A28: Principal value | B28: 0 | C28: 0 | D28: 0 | E28: 0 | F28: 0 | G28: 0 | H28: =B21 -> 325500
A29: Coupons and principal | B29: =B27+B28 -> 16275 | C29: =C27+C28 -> 16275 | D29: =D27+D28 -> 16275 | E29: =E27+E28 -> 16275 | F29: =F27+F28 -> 16275 | G29: =G27+G28 -> 16275 | H29: =H27+H28 -> 341775
A32: Equity (5 points) | B32: =B5/3 -> 325500
A34: Year | B34: Year 0
A36: Net Income/Loss | B36: ='P2 History'!N42 -> 1399000
A37: Dividends | B37: =B36*'P3 Inputs'!B11 -> 699500
A39: Cost of Equity | B39: =(((B36*'P5 Cost of capital'!C11)/'P3 Inputs'!B19))*(1+'P5 Cost of capital'!B13)/'P3 Inputs'!B18+'P3 Inputs'!B13 -> 0.05
A42: WACC
B43: Amount | C43: Weight | D43: Cost of capital
A44: Bank Loan | B44: =B7 -> 325500 | C44: =B44/(B44+B45+B46) -> 0.33333333 | D44: =B9*(1-'P3 Inputs'!B8) -> 0.0616
A45: Bonds | B45: =B19 -> 325500 | C45: =B45/(B44+B45+B46) -> 0.33333333 | D45: =B22*(1-'P3 Inputs'!B8) -> 0.04
A46: Equity | B46: =B32 -> 325500 | C46: =B46/(B44+B45+B46) -> 0.33333333 | D46: =B39 -> 0.05
A48: Total CAPEX Financing | B48: =SUM(B44:B46) -> 976500
A51: WACC | B51: =(C44*D44)+(C45*D45)+(C46*D46) -> 0.050533333
B52: 0.0505

Sheet P6 P&L and BS Projection
B1: Financial Statements Statement of Company | G1: Points | H1: 15
B3: Year 0 | C3: Year 1 | D3: Year 2 | E3: Year 3 | F3: Year 4 | G3: Year 5 | H3: Year 6 | I3: Year 7
A5: P&L (in thousands) (7 points)
A6: Total Sales | B6: ='P2 History'!N24 -> 9765000 | C6: =B6*(1+'P3 Inputs'!C6) -> 12206250 | D6: =C6*(1+'P3 Inputs'!D6) -> 14647500 | E6: =D6*(1+'P3 Inputs'!E6) -> 16112250 | F6: =E6*(1+'P3 Inputs'!F6) -> 17723475 | G6: =F6*(1+'P3 Inputs'!G6) -> 19495823 | H6: =G6*(1+'P3 Inputs'!H6) -> 21445405 | I6: =H6*(1+'P3 Inputs'!I6) -> 23589945
A7: COGS | B7: =B6*'P3 Inputs'!B7 -> 4882500 | C7: =C6*'P3 Inputs'!C7 -> 6103125 | D7: =D6*'P3 Inputs'!D7 -> 7323750 | E7: =E6*'P3 Inputs'!E7 -> 8056125 | F7: =F6*'P3 Inputs'!F7 -> 8861737.5 | G7: =G6*'P3 Inputs'!G7 -> 9747911.3 | H7: =H6*'P3 Inputs'!H7 -> 10722702 | I7: =I6*'P3 Inputs'!I7 -> 11794973
A8: Gross earnings | C8: =C6-C7 -> 6103125 | D8: =D6-D7 -> 7323750 | E8: =E6-E7 -> 8056125 | F8: =F6-F7 -> 8861737.5 | G8: =G6-G7 -> 9747911.3 | H8: =H6-H7 -> 10722702 | I8: =I6-I7 -> 11794973
K9: Assumptions
A10: General and administrative costs | C10: =C7*'P3 Inputs'!C16 -> 305156.25 | D10: =D7*'P3 Inputs'!D16 -> 366187.5 | E10: =E7*'P3 Inputs'!E16 -> 402806.25 | F10: =F7*'P3 Inputs'!F16 -> 443086.88 | G10: =G7*'P3 Inputs'!G16 -> 487395.56 | H10: =H7*'P3 Inputs'!H16 -> 536135.12 | I10: =I7*'P3 Inputs'!I16 -> 589748.63
A11: Amortisation | B11: =B37*J11 -> 23200 | C11: =C37*J11 -> 42730 | D11: =D37*J11 -> 42730 | E11: =E37*J11 -> 42730 | F11: =F37*J11 -> 42730 | G11: =G37*J11 -> 42730 | H11: =H37*J11 -> 42730 | I11: =I37*J11 -> 42730 | J11: 0.02 | K11: Total tangible assets
A12: EBIT | C12: =C10-C11 -> 262426.25 | D12: =D10-D11 -> 323457.5 | E12: =E10-E11 -> 360076.25 | F12: =F10-F11 -> 400356.88 | G12: =G10-G11 -> 444665.56 | H12: =H10-H11 -> 493405.12 | I12: =I10-I11 -> 547018.63
A14: Financial Interests | C14: =(C46+C49)*'P3 Inputs'!C9 -> -698132.91 | D14: =(D46+D49)*'P3 Inputs'!D9 -> -773506.13 | E14: =(E46+E49)*'P3 Inputs'!E9 -> -846020.19 | F14: =(F46+F49)*'P3 Inputs'!F9 -> -921847.04 | G14: =(G46+G49)*'P3 Inputs'!G9 -> -1001192.8 | H14: =(H46+H49)*'P3 Inputs'!H9 -> -1084280.2 | I14: =(I46+I49)*'P3 Inputs'!I9 -> -1132143.1
A16: EBT | C16: =C12-C14 -> 960559.16 | D16: =D12-D14 -> 1096963.6 | E16: =E12-E14 -> 1206096.4 | F16: =F12-F14 -> 1322203.9 | G16: =G12-G14 -> 1445858.4 | H16: =H12-H14 -> 1577685.3 | I16: =I12-I14 -> 1679161.7
A17: Income tax | C17: =C16*'P3 Inputs'!C8 -> 192111.83 | D17: =D16*'P3 Inputs'!D8 -> 219392.73 | E17: =E16*'P3 Inputs'!E8 -> 241219.29 | F17: =F16*'P3 Inputs'!F8 -> 264440.78 | G17: =G16*'P3 Inputs'!G8 -> 289171.67 | H17: =H16*'P3 Inputs'!H8 -> 315537.07 | I17: =I16*'P3 Inputs'!I8 -> 335832.35
A18: Net income/Loss | C18: =C16-C17 -> 768447.33 | D18: =D16-D17 -> 877570.9 | E18: =E16-E17 -> 964877.15 | F18: =F16-F17 -> 1057763.1 | G18: =G16-G17 -> 1156686.7 | H18: =H16-H17 -> 1262148.3 | I18: =I16-I17 -> 1343329.4
A20: Number of stocks | C20: ='P3 Inputs'!B19 -> 10500000000 | D20: =C20 -> 10500000000 | E20: =C20 -> 10500000000 | F20: =C20 -> 10500000000 | G20: =C20 -> 10500000000 | H20: =C20 -> 10500000000 | I20: =C20 -> 10500000000
A21: EPS | C21: =C18/C20 -> 7.318546e-05 | D21: =D18/D20 -> 8.3578181e-05 | E21: =E18/E20 -> 9.1893062e-05 | F21: =F18/F20 -> 0.00010073935 | G21: =G18/G20 -> 0.00011016064 | H21: =H18/H20 -> 0.0001202046 | I21: =I18/I20 -> 0.00012793613
A23: Net income/Loss share
A24: Dividends | C24: =C18*'P3 Inputs'!C11 -> 384223.66 | D24: =D18*'P3 Inputs'!D11 -> 438785.45 | E24: =E18*'P3 Inputs'!E11 -> 482438.58 | F24: =F18*'P3 Inputs'!F11 -> 528881.57 | G24: =G18*'P3 Inputs'!G11 -> 578343.34 | H24: =H18*'P3 Inputs'!H11 -> 631074.13 | I24: =I18*'P3 Inputs'!I11 -> 671664.7
A25: Retained earnings/Deferred losses | C25: =C18-C24 -> 384223.66 | D25: =D18-D24 -> 438785.45 | E25: =E18-E24 -> 482438.58 | F25: =F18-F24 -> 528881.57 | G25: =G18-G24 -> 578343.34 | H25: =H18-H24 -> 631074.13 | I25: =I18-I24 -> 671664.7
B28: Year 0 | C28: Year 1 | D28: Year 2 | E28: Year 3 | F28: Year 4 | G28: Year 5 | H28: Year 6 | I28: Year 7
A29: BALANCE SHEET (in thousands) (8 points)
A30: ASSETS
A31: Current assets
A32: Cash | B32: ='P2 History'!E24 -> 1130000 | C32: =B32*(1+'P3 Inputs'!C22) -> 1243000 | D32: =C32*(1+'P3 Inputs'!D22) -> 1367300 | E32: =D32*(1+'P3 Inputs'!E22) -> 1504030 | F32: =E32*(1+'P3 Inputs'!F22) -> 1654433 | G32: =F32*(1+'P3 Inputs'!G22) -> 1819876.3 | H32: =G32*(1+'P3 Inputs'!H22) -> 2001863.9 | I32: =H32*(1+'P3 Inputs'!I22) -> 2202050.3
A33: Receivables | C33: =B33*(1+'P3 Inputs'!C23) -> 0 | D33: =C33*(1+'P3 Inputs'!D23) -> 0 | E33: =D33*(1+'P3 Inputs'!E23) -> 0 | F33: =E33*(1+'P3 Inputs'!F23) -> 0 | G33: =F33*(1+'P3 Inputs'!G23) -> 0 | H33: =G33*(1+'P3 Inputs'!H23) -> 0 | I33: =H33*(1+'P3 Inputs'!I23) -> 0
A34: Stocks | C34: =B34*(1+'P3 Inputs'!C24) -> 0 | D34: =C34*(1+'P3 Inputs'!D24) -> 0 | E34: =D34*(1+'P3 Inputs'!E24) -> 0 | F34: =E34*(1+'P3 Inputs'!F24) -> 0 | G34: =F34*(1+'P3 Inputs'!G24) -> 0 | H34: =G34*(1+'P3 Inputs'!H24) -> 0 | I34: =H34*(1+'P3 Inputs'!I24) -> 0
A35: Total short term assets | B35: =SUM(B32:B34) -> 1130000 | C35: =SUM(C32:C34) -> 1243000 | D35: =SUM(D32:D34) -> 1367300 | E35: =SUM(E32:E34) -> 1504030 | F35: =SUM(F32:F34) -> 1654433 | G35: =SUM(G32:G34) -> 1819876.3 | H35: =SUM(H32:H34) -> 2001863.9 | I35: =SUM(I32:I34) -> 2202050.3
A37: Tangible assets | B37: ='P3 Inputs'!B30 -> 1160000 | C37: =B37+'P5 Cost of capital'!B5 -> 2136500 | D37: =C37 -> 2136500 | E37: =D37 -> 2136500 | F37: =E37 -> 2136500 | G37: =F37 -> 2136500 | H37: =G37 -> 2136500 | I37: =H37 -> 2136500
A38: Accumulated amortization | C38: ='P4 Assets amortization'!C13 -> 847500 | D38: ='P4 Assets amortization'!D13 -> 1341000 | E38: ='P4 Assets amortization'!E13 -> 1834500 | F38: ='P4 Assets amortization'!F13 -> 2328000 | G38: ='P4 Assets amortization'!G13 -> 2821500 | H38: ='P4 Assets amortization'!H13 -> 3315000 | I38: ='P4 Assets amortization'!I13 -> 3315000
A39: Net assets | B39: =B37-B38 -> 1160000 | C39: =C37-C38 -> 1289000 | D39: =D37-D38 -> 795500 | E39: =E37-E38 -> 302000 | F39: =F37-F38 -> -191500 | G39: =G37-G38 -> -685000 | H39: =H37-H38 -> -1178500 | I39: =I37-I38 -> -1178500
A41: TOTAL ASSETS | B41: ='P2 History'!E37 -> 14963000 | C41: =C35+C39 -> 2532000 | D41: =D35+D39 -> 2162800 | E41: =E35+E39 -> 1806030 | F41: =F35+F39 -> 1462933 | G41: =G35+G39 -> 1134876.3 | H41: =H35+H39 -> 823363.93 | I41: =I35+I39 -> 1023550.3
A43: EQUITY AND LIABILITIES
A44: Current liabilities
A45: Payables | C45: =C7*'P3 Inputs'!C26 -> 854437.5 | D45: =D7*'P3 Inputs'!D26 -> 1025325 | E45: =E7*'P3 Inputs'!E26 -> 1127857.5 | F45: =F7*'P3 Inputs'!F26 -> 1240643.3 | G45: =G7*'P3 Inputs'!G26 -> 1364707.6 | H45: =H7*'P3 Inputs'!H26 -> 1501178.3 | I45: =I7*'P3 Inputs'!I26 -> 1651296.2
A46: Other Liabilities | C46: =C7*'P3 Inputs'!C27 -> 122062.5 | D46: =D7*'P3 Inputs'!D27 -> 146475 | E46: =E7*'P3 Inputs'!E27 -> 161122.5 | F46: =F7*'P3 Inputs'!F27 -> 177234.75 | G46: =G7*'P3 Inputs'!G27 -> 194958.23 | H46: =H7*'P3 Inputs'!H27 -> 214454.05 | I46: =I7*'P3 Inputs'!I27 -> 235899.45
A47: Total short term liabilities | C47: =C45+C46 -> 976500 | D47: =D45+D46 -> 1171800 | E47: =E45+E46 -> 1288980 | F47: =F45+F46 -> 1417878 | G47: =G45+G46 -> 1559665.8 | H47: =H45+H46 -> 1715632.4 | I47: =I45+I46 -> 1887195.6
A49: Long term debt | B49: =B50-B47 -> 5628000 | C49: =C50-C47 -> -9188723.7 | D49: =D50-D47 -> -10192009 | E49: =E50-E47 -> -11148398 | F49: =F50-F47 -> -12149274 | G49: =G50-G47 -> -13197462 | H49: =H50-H47 -> -14296015 | I49: =I50-I47 -> -14939057
A50: Total Liabilities | B50: =B57-B55 -> 5628000 | C50: =C57-C55 -> -8212223.7 | D50: =D57-D55 -> -9020209.1 | E50: =E57-E55 -> -9859417.7 | F50: =F57-F55 -> -10731396 | G50: =G57-G55 -> -11637796 | H50: =H57-H55 -> -12580383 | I50: =I57-I55 -> -13051861
A52: Equity
A53: Shareholders Equity | B53: ='P3 Inputs'!B28 -> 9335000 | C53: =B53+'P5 Cost of capital'!B32 -> 9660500 | D53: =C53 -> 9660500 | E53: =D53 -> 9660500 | F53: =E53 -> 9660500 | G53: =F53 -> 9660500 | H53: =G53 -> 9660500 | I53: =H53 -> 9660500
...

Sheet P7 CF's projection
B1: Cash Flow Statement of Company | G1: Points | H1: 10
A2: (amounts in thousands)
B3: Year 0 | C3: Year 1 | D3: Year 2 | E3: Year 3 | F3: Year 4 | G3: Year 5 | H3: Year 6 | I3: Year 7
A4: Cash Flow statement (in thousand)
A5: CF from Operating activities
A6: Net income/loss | D6: ='P6 P&L and BS Projection'!D18 -> 877570.9 | E6: ='P6 P&L and BS Projection'!E18 -> 964877.15 | F6: ='P6 P&L and BS Projection'!F18 -> 1057763.1 | G6: ='P6 P&L and BS Projection'!G18 -> 1156686.7 | H6: ='P6 P&L and BS Projection'!H18 -> 1262148.3 | I6: ='P6 P&L and BS Projection'!I18 -> 1343329.4
A7: + Amortization | D7: ='P6 P&L and BS Projection'!D38-'P6 P&L and BS Projection'!C38 -> 493500 | E7: ='P6 P&L and BS Projection'!E38-'P6 P&L and BS Projection'!D38 -> 493500 | F7: ='P6 P&L and BS Projection'!F38-'P6 P&L and BS Projection'!E38 -> 493500 | G7: ='P6 P&L and BS Projection'!G38-'P6 P&L and BS Projection'!F38 -> 493500 | H7: ='P6 P&L and BS Projection'!H38-'P6 P&L and BS Projection'!G38 -> 493500 | I7: ='P6 P&L and BS Projection'!I38-'P6 P&L and BS Projection'!H38 -> 0
A8: - Receivables | D8: =-('P6 P&L and BS Projection'!D33-'P6 P&L and BS Projection'!C33) -> 0 | E8: =-('P6 P&L and BS Projection'!E33-'P6 P&L and BS Projection'!D33) -> 0 | F8: =-('P6 P&L and BS Projection'!F33-'P6 P&L and BS Projection'!E33) -> 0 | G8: =-('P6 P&L and BS Projection'!G33-'P6 P&L and BS Projection'!F33) -> 0 | H8: =-('P6 P&L and BS Projection'!H33-'P6 P&L and BS Projection'!G33) -> 0 | I8: =-('P6 P&L and BS Projection'!I33-'P6 P&L and BS Projection'!H33) -> 0
A9: - Stocks | D9: =-('P6 P&L and BS Projection'!D34-'P6 P&L and BS Projection'!C34) -> 0 | E9: =-('P6 P&L and BS Projection'!E34-'P6 P&L and BS Projection'!D34) -> 0 | F9: =-('P6 P&L and BS Projection'!F34-'P6 P&L and BS Projection'!E34) -> 0 | G9: =-('P6 P&L and BS Projection'!G34-'P6 P&L and BS Projection'!F34) -> 0 | H9: =-('P6 P&L and BS Projection'!H34-'P6 P&L and BS Projection'!G34) -> 0 | I9: =-('P6 P&L and BS Projection'!I34-'P6 P&L and BS Projection'!H34) -> 0
A10: + Payables | D10: ='P6 P&L and BS Projection'!D45-'P6 P&L and BS Projection'!C45 -> 170887.5 | E10: ='P6 P&L and BS Projection'!E45-'P6 P&L and BS Projection'!D45 -> 102532.5 | F10: ='P6 P&L and BS Projection'!F45-'P6 P&L and BS Projection'!E45 -> 112785.75 | G10: ='P6 P&L and BS Projection'!G45-'P6 P&L and BS Projection'!F45 -> 124064.33 | H10: ='P6 P&L and BS Projection'!H45-'P6 P&L and BS Projection'!G45 -> 136470.76 | I10: ='P6 P&L and BS Projection'!I45-'P6 P&L and BS Projection'!H45 -> 150117.83
A11: + Other Liabilities | D11: ='P6 P&L and BS Projection'!D46-'P6 P&L and BS Projection'!C46 -> 24412.5 | E11: ='P6 P&L and BS Projection'!E46-'P6 P&L and BS Projection'!D46 -> 14647.5 | F11: ='P6 P&L and BS Projection'!F46-'P6 P&L and BS Projection'!E46 -> 16112.25 | G11: ='P6 P&L and BS Projection'!G46-'P6 P&L and BS Projection'!F46 -> 17723.475 | H11: ='P6 P&L and BS Projection'!H46-'P6 P&L and BS Projection'!G46 -> 19495.823 | I11: ='P6 P&L and BS Projection'!I46-'P6 P&L and BS Projection'!H46 -> 21445.405
A12: Total CF from operating activities | D12: =SUM(D6:D11) -> 1566370.9 | E12: =SUM(E6:E11) -> 1575557.2 | F12: =SUM(F6:F11) -> 1680161.1 | G12: =SUM(G6:G11) -> 1791974.5 | H12: =SUM(H6:H11) -> 1911614.8 | I12: =SUM(I6:I11) -> 1514892.6
A14: CF from Investment activities
A15: - CAPEX | D15: ='P6 P&L and BS Projection'!D37-'P6 P&L and BS Projection'!C37 -> 0 | E15: ='P6 P&L and BS Projection'!E37-'P6 P&L and BS Projection'!D37 -> 0 | F15: ='P6 P&L and BS Projection'!F37-'P6 P&L and BS Projection'!E37 -> 0 | G15: ='P6 P&L and BS Projection'!G37-'P6 P&L and BS Projection'!F37 -> 0 | H15: ='P6 P&L and BS Projection'!H37-'P6 P&L and BS Projection'!G37 -> 0 | I15: ='P6 P&L and BS Projection'!I37-'P6 P&L and BS Projection'!H37 -> 0
A16: Total CF from Investment activities | D16: =D15 -> 0 | E16: =E15 -> 0 | F16: =F15 -> 0 | G16: =G15 -> 0 | H16: =H15 -> 0 | I16: =I15 -> 0
A18: CF from finance activities
A19: + Long term debt | D19: ='P6 P&L and BS Projection'!D49-'P6 P&L and BS Projection'!C49 -> -1003285.5 | E19: ='P6 P&L and BS Projection'!E49-'P6 P&L and BS Projection'!D49 -> -956388.58 | F19: ='P6 P&L and BS Projection'!F49-'P6 P&L and BS Projection'!E49 -> -1000876.6 | G19: ='P6 P&L and BS Projection'!G49-'P6 P&L and BS Projection'!F49 -> -1048187.8 | H19: ='P6 P&L and BS Projection'!H49-'P6 P&L and BS Projection'!G49 -> -1098553.1 | I19: ='P6 P&L and BS Projection'!I49-'P6 P&L and BS Projection'!H49 -> -643041.54
A20: + Equity | D20: ='P6 P&L and BS Projection'!D53-'P6 P&L and BS Projection'!C53 -> 0 | E20: ='P6 P&L and BS Projection'!E53-'P6 P&L and BS Projection'!D53 -> 0 | F20: ='P6 P&L and BS Projection'!F53-'P6 P&L and BS Projection'!E53 -> 0 | G20: ='P6 P&L and BS Projection'!G53-'P6 P&L and BS Projection'!F53 -> 0 | H20: ='P6 P&L and BS Projection'!H53-'P6 P&L and BS Projection'!G53 -> 0 | I20: ='P6 P&L and BS Projection'!I53-'P6 P&L and BS Projection'!H53 -> 0
A21: - Dividends | D21: =-('P6 P&L and BS Projection'!D24) -> -438785.45 | E21: =-('P6 P&L and BS Projection'!E24) -> -482438.58 | F21: =-('P6 P&L and BS Projection'!F24) -> -528881.57 | G21: =-('P6 P&L and BS Projection'!G24) -> -578343.34 | H21: =-('P6 P&L and BS Projection'!H24) -> -631074.13 | I21: =-('P6 P&L and BS Projection'!I24) -> -671664.7
A22: Total CF from finance activities | D22: =D19+D20+D21 -> -1442070.9 | E22: =E19+E20+E21 -> -1438827.2 | F22: =F19+F20+F21 -> -1529758.1 | G22: =G19+G20+G21 -> -1626531.2 | H22: =H19+H20+H21 -> -1729627.2 | I22: =I19+I20+I21 -> -1314706.2
A24: Change of cash | D24: =D12+D16+D22 -> 124300 | E24: =E12+E16+E22 -> 136730 | F24: =F12+F16+F22 -> 150403 | G24: =G12+G16+G22 -> 165443.3 | H24: =H12+H16+H22 -> 181987.63 | I24: =I12+I16+I22 -> 200186.39
A25: Cash at beggining period | D25: ='P6 P&L and BS Projection'!C32 -> 1243000 | E25: ='P6 P&L and BS Projection'!D32 -> 1367300 | F25: ='P6 P&L and BS Projection'!E32 -> 1504030 | G25: ='P6 P&L and BS Projection'!F32 -> 1654433 | H25: ='P6 P&L and BS Projection'!G32 -> 1819876.3 | I25: ='P6 P&L and BS Projection'!H32 -> 2001863.9
A26: Cash at end of period | C26: 1243000 | D26: =D24+D25 -> 1367300 | E26: =E24+E25 -> 1504030 | F26: =F24+F25 -> 1654433 | G26: =G24+G25 -> 1819876.3 | H26: =H24+H25 -> 2001863.9 | I26: =I24+I25 -> 2202050.3
A28: Total cash from Balance sheet | C28: ='P6 P&L and BS Projection'!C32 -> 1243000 | D28: ='P6 P&L and BS Projection'!D32 -> 1367300 | E28: ='P6 P&L and BS Projection'!E32 -> 1504030 | F28: ='P6 P&L and BS Projection'!F32 -> 1654433 | G28: ='P6 P&L and BS Projection'!G32 -> 1819876.3 | H28: ='P6 P&L and BS Projection'!H32 -> 2001863.9 | I28: ='P6 P&L and BS Projection'!I32 -> 2202050.3
A30: Check | C30: =IF(C28=C26,"OK","NOT OK") -> OK | D30: =IF(D28=D26,"OK","NOT OK") -> OK | E30: =IF(E28=E26,"OK","NOT OK") -> OK | F30: =IF(F28=F26,"OK","NOT OK") -> OK | G30: =IF(G28=G26,"OK","NOT OK") -> OK | H30: =IF(H28=H26,"OK","NOT OK") -> OK | I30: =IF(I28=I26,"OK","NOT OK") -> OK

Sheet P8 Scenarios
B1: Scenarios Analysis | E1: Points | F1: 10
A2: (amounts in thousands)
A4: SCENARIO 1 BASE CASE : (4 points)
B5: Year 0 | C5: Year 1 | D5: Year 2 | E5: Year 3 | F5: Year 4 | G5: Year 5 | H5: Year 6 | I5: Year 7
A8: CAPEX | B8: =-('P5 Cost of capital'!B5) -> -976500
A9: Cash Flows | C9: ='P7 CF''s projection'!C26*'P3 Inputs'!B31 -> 248600 | D9: ='P7 CF''s projection'!D26*'P3 Inputs'!B31 -> 273460 | E9: ='P7 CF''s projection'!E26*'P3 Inputs'!B31 -> 300806 | F9: ='P7 CF''s projection'!F26*'P3 Inputs'!B31 -> 330886.6 | G9: ='P7 CF''s projection'!G26*'P3 Inputs'!B31 -> 363975.26 | H9: ='P7 CF''s projection'!H26*'P3 Inputs'!B31 -> 400372.79 | I9: ='P7 CF''s projection'!I26*'P3 Inputs'!B31 -> 440410.06
A11: Total Cash Flows | B11: =B8 -> -976500 | C11: =C9 -> 248600 | D11: =D9 -> 273460 | E11: =E9 -> 300806 | F11: =F9 -> 330886.6 | G11: =G9 -> 363975.26 | H11: =H9 -> 400372.79 | I11: =I9 -> 440410.06
A14: NPV 1 | B14: =B11+NPV('P5 Cost of capital'!B51,'P8 Scenarios'!C11:I11) -> 933244.03 | D14: NPV>0 means investment is profitable
A15: IRR 1 | B15: =IRR(B11:I11) -> 0.25128873 | D15: IRR has to be compared with cost of capital. In this company IRR is higher then cost of capital which is acceptable.
A17: SCENARIO 2 WORST CASE : (3 points)
B18: Year 0 | C18: Year 1 | D18: Year 2 | E18: Year 3 | F18: Year 4 | G18: Year 5 | H18: Year 6 | I18: Year 7
A21: CAPEX | B21: =(B8)*(1+'P3 Inputs'!B32) -> -1171800
A22: Cash Flows | C22: ='P7 CF''s projection'!C26*(1-'P3 Inputs'!B33) -> 1180850 | D22: ='P7 CF''s projection'!D26*(1-'P3 Inputs'!B33) -> 1298935 | E22: ='P7 CF''s projection'!E26*(1-'P3 Inputs'!B33) -> 1428828.5 | F22: ='P7 CF''s projection'!F26*(1-'P3 Inputs'!B33) -> 1571711.3 | G22: ='P7 CF''s projection'!G26*(1-'P3 Inputs'!B33) -> 1728882.5 | H22: ='P7 CF''s projection'!H26*(1-'P3 Inputs'!B33) -> 1901770.7 | I22: ='P7 CF''s projection'!I26*(1-'P3 Inputs'!B33) -> 2091947.8
A24: Total Cash Flows | B24: =B21 -> -1171800 | C24: =C22 -> 1180850 | D24: =D22 -> 1298935 | E24: =E22 -> 1428828.5 | F24: =F22 -> 1571711.3 | G24: =G22 -> 1728882.5 | H24: =H22 -> 1901770.7 | I24: =I22 -> 2091947.8
A27: NPV 2 | B27: =B24+NPV('P5 Cost of capital'!B51,'P8 Scenarios'!C24:I24) -> 7899484.2
A28: IRR 2 | B28: =IRR(B24:I24) -> 1.0966992
A30: SCENARIO 3 BEST CASE : (3 points)
B31: Year 0 | C31: Year 1 | D31: Year 2 | E31: Year 3 | F31: Year 4 | G31: Year 5 | H31: Year 6 | I31: Year 7
A34: CAPEX | B34: =B8*(1-'P3 Inputs'!B34) -> -830025
A35: Cash Flows | C35: ='P7 CF''s projection'!C26*(1+'P3 Inputs'!B35) -> 1317580 | D35: ='P7 CF''s projection'!D26*(1+'P3 Inputs'!B35) -> 1449338 | E35: ='P7 CF''s projection'!E26*(1+'P3 Inputs'!B35) -> 1594271.8 | F35: ='P7 CF''s projection'!F26*(1+'P3 Inputs'!B35) -> 1753699 | G35: ='P7 CF''s projection'!G26*(1+'P3 Inputs'!B35) -> 1929068.9 | H35: ='P7 CF''s projection'!H26*(1+'P3 Inputs'!B35) -> 2121975.8 | I35: ='P7 CF''s projection'!I26*(1+'P3 Inputs'!B35) -> 2334173.3
A37: Total Cash Flows | B37: =B34 -> -830025 | C37: =C35 -> 1317580 | D37: =D35 -> 1449338 | E37: =E35 -> 1594271.8 | F37: =F35 -> 1753699 | G37: =G35 -> 1929068.9 | H37: =H35 -> 2121975.8 | I37: =I35 -> 2334173.3
A40: NPV 3 | B40: =B37+NPV('P5 Cost of capital'!B51,'P8 Scenarios'!C37:I37) -> 9291618.4
A41: IRR 3 | B41: =IRR(B37:I37) -> 1.6843176

Sheet P9 NWC
C1: Net Working Capital | G1: Points | H1: 5
A2: (amounts in thousands)
B3: Year 1 | C3: Year 2 | D3: Year 3 | E3: Year 4 | F3: Year 5 | G3: Year 6 | H3: Year 7
A4: Curent Assets
A6: Receivables | B6: ='P6 P&L and BS Projection'!C33 -> 0 | C6: ='P6 P&L and BS Projection'!D33 -> 0 | D6: ='P6 P&L and BS Projection'!E33 -> 0 | E6: ='P6 P&L and BS Projection'!F33 -> 0 | F6: ='P6 P&L and BS Projection'!G33 -> 0 | G6: ='P6 P&L and BS Projection'!H33 -> 0 | H6: ='P6 P&L and BS Projection'!I33 -> 0
A7: Stocks | B7: ='P6 P&L and BS Projection'!C34 -> 0 | C7: ='P6 P&L and BS Projection'!D34 -> 0 | D7: ='P6 P&L and BS Projection'!E34 -> 0 | E7: ='P6 P&L and BS Projection'!F34 -> 0 | F7: ='P6 P&L and BS Projection'!G34 -> 0 | G7: ='P6 P&L and BS Projection'!H34 -> 0 | H7: ='P6 P&L and BS Projection'!I34 -> 0
A9: Total Current assets | B9: =B6+B7 -> 0 | C9: =C6+C7 -> 0 | D9: =D6+D7 -> 0 | E9: =E6+E7 -> 0 | F9: =F6+F7 -> 0 | G9: =G6+G7 -> 0 | H9: =H6+H7 -> 0
A11: Curent Liabilities
A13: Payables | B13: ='P6 P&L and BS Projection'!C45 -> 854437.5 | C13: ='P6 P&L and BS Projection'!D45 -> 1025325 | D13: ='P6 P&L and BS Projection'!E45 -> 1127857.5 | E13: ='P6 P&L and BS Projection'!F45 -> 1240643.3 | F13: ='P6 P&L and BS Projection'!G45 -> 1364707.6 | G13: ='P6 P&L and BS Projection'!H45 -> 1501178.3 | H13: ='P6 P&L and BS Projection'!I45 -> 1651296.2
A14: Other Liabilities | B14: ='P6 P&L and BS Projection'!C46 -> 122062.5 | C14: ='P6 P&L and BS Projection'!D46 -> 146475 | D14: ='P6 P&L and BS Projection'!E46 -> 161122.5 | E14: ='P6 P&L and BS Projection'!F46 -> 177234.75 | F14: ='P6 P&L and BS Projection'!G46 -> 194958.23 | G14: ='P6 P&L and BS Projection'!H46 -> 214454.05 | H14: ='P6 P&L and BS Projection'!I46 -> 235899.45
A16: Total Current liabilities | B16: =B13+B14 -> 976500 | C16: =C13+C14 -> 1171800 | D16: =D13+D14 -> 1288980 | E16: =E13+E14 -> 1417878 | F16: =F13+F14 -> 1559665.8 | G16: =G13+G14 -> 1715632.4 | H16: =H13+H14 -> 1887195.6
A18: NWC | B18: =B9-B16 -> -976500 | C18: =C9-C16 -> -1171800 | D18: =D9-D16 -> -1288980 | E18: =E9-E16 -> -1417878 | F18: =F9-F16 -> -1559665.8 | G18: =G9-G16 -> -1715632.4 | H18: =H9-H16 -> -1887195.6
A20: Increase/Decrease of NWC | C20: =(-B18)-(-C18) -> -195300 | D20: =(-C18)-(-D18) -> -117180 | E20: =(-D18)-(-E18) -> -128898 | F20: =(-E18)-(-F18) -> -141787.8 | G20: =(-F18)-(-G18) -> -155966.58 | H20: =(-G18)-(-H18) -> -171563.24

Sheet P10 Valuation
B1: Company Valuation | F1: Points | G1: 15
A3: (amounts in thousands)
A5: FCF CALCULATION (8 points)
A7: (amounts in thousands)
B9: YEARS | C9: 1 | D9: 2 | E9: 3 | F9: 4 | G9: 5 | H9: 6 | I9: 7 | J9: >7
A11: EBIT | C11: ='P6 P&L and BS Projection'!C12 -> 262426.25 | D11: ='P6 P&L and BS Projection'!D12 -> 323457.5 | E11: ='P6 P&L and BS Projection'!E12 -> 360076.25 | F11: ='P6 P&L and BS Projection'!F12 -> 400356.88 | G11: ='P6 P&L and BS Projection'!G12 -> 444665.56 | H11: ='P6 P&L and BS Projection'!H12 -> 493405.12 | I11: ='P6 P&L and BS Projection'!I12 -> 547018.63
A12: Income tax | C12: =C11*'P3 Inputs'!C8 -> 52485.25 | D12: =D11*'P3 Inputs'!D8 -> 64691.5 | E12: =E11*'P3 Inputs'!E8 -> 72015.25 | F12: =F11*'P3 Inputs'!F8 -> 80071.375 | G12: =G11*'P3 Inputs'!G8 -> 88933.113 | H12: =H11*'P3 Inputs'!H8 -> 98681.024 | I12: =I11*'P3 Inputs'!I8 -> 109403.73
A13: NOPAT | C13: =C11-C12 -> 209941 | D13: =D11-D12 -> 258766 | E13: =E11-E12 -> 288061 | F13: =F11-F12 -> 320285.5 | G13: =G11-G12 -> 355732.45 | H13: =H11-H12 -> 394724.1 | I13: =I11-I12 -> 437614.9
A14: +AMORTIZATION | C14: ='P6 P&L and BS Projection'!C11 -> 42730 | D14: ='P6 P&L and BS Projection'!D11 -> 42730 | E14: ='P6 P&L and BS Projection'!E11 -> 42730 | F14: ='P6 P&L and BS Projection'!F11 -> 42730 | G14: ='P6 P&L and BS Projection'!G11 -> 42730 | H14: ='P6 P&L and BS Projection'!H11 -> 42730 | I14: ='P6 P&L and BS Projection'!I11 -> 42730
A15: -CAPEX | C15: =-'P5 Cost of capital'!B5 -> -976500
A16: - NWC change | D16: ='P9 NWC'!C20 -> -195300 | E16: ='P9 NWC'!D20 -> -117180 | F16: ='P9 NWC'!E20 -> -128898 | G16: ='P9 NWC'!F20 -> -141787.8 | H16: ='P9 NWC'!G20 -> -155966.58 | I16: ='P9 NWC'!H20 -> -171563.24
A18: FCF | C18: =C13+C14+C15-C16 -> -723829 | D18: =D13+D14+D15-D16 -> 496796 | E18: =E13+E14+E15-E16 -> 447971 | F18: =F13+F14+F15-F16 -> 491913.5 | G18: =G13+G14+G15-G16 -> 540250.25 | H18: =H13+H14+H15-H16 -> 593420.68 | I18: =I13+I14+I15-I16 -> 651908.14
A19: Terminal value | J19: =I18*(1+'P3 Inputs'!B36)/('P5 Cost of capital'!B52-'P3 Inputs'!B36) -> 21801518
A20: Total FCF with Terminal value | C20: =C18 -> -723829 | D20: =D18 -> 496796 | E20: =E18 -> 447971 | F20: =F18 -> 491913.5 | G20: =G18 -> 540250.25 | H20: =H18 -> 593420.68 | I20: =SUM(C21:H21)+J19 -> 23216866
A21: DFCF | C21: =C18/(1+'P5 Cost of capital'!B52)^C9 -> -689032.84 | D21: =D18/(1+'P5 Cost of capital'!B52)^D9 -> 450179.77 | E21: =E18/(1+'P5 Cost of capital'!B52)^E9 -> 386421.9 | F21: =F18/(1+'P5 Cost of capital'!B52)^F9 -> 403928.52 | G21: =G18/(1+'P5 Cost of capital'!B52)^G9 -> 422293.79 | H21: =H18/(1+'P5 Cost of capital'!B52)^H9 -> 441556.55 | I21: =I18/(1+'P5 Cost of capital'!B51)^I9 -> 461655
A23: Company value | B23: =I20 -> 23216866
A24: Cash | B24: ='P6 P&L and BS Projection'!B32 -> 1130000
A25: Long term debt | B25: ='P6 P&L and BS Projection'!B49 -> 5628000
A27: Equity based on FCF | B27: =B23+B24-B25 -> 18718866
A28: Number of Shares | B28: ='P3 Inputs'!B19 -> 10500000000
A29: Stock price based on FCF * 1000 | B29: =(B27/B28)*1000 -> 1.7827491
A32: DIVIDENDS CALCULATION (7 points) | C32: 1 | D32: 2 | E32: 3 | F32: 4 | G32: 5 | H32: 6 | I32: 7 | J32: >7
A34: Dividends | C34: ='P6 P&L and BS Projection'!C24 -> 384223.66 | D34: ='P6 P&L and BS Projection'!D24 -> 438785.45 | E34: ='P6 P&L and BS Projection'!E24 -> 482438.58 | F34: ='P6 P&L and BS Projection'!F24 -> 528881.57 | G34: ='P6 P&L and BS Projection'!G24 -> 578343.34 | H34: ='P6 P&L and BS Projection'!H24 -> 631074.13 | I34: ='P6 P&L and BS Projection'!I24 -> 671664.7
A35: Terminal Value | J35: =I34/'P5 Cost of capital'!B39 -> 13433294
A36: Total Dividends with Terminal value | C36: =C34 -> 384223.66 | D36: =D34 -> 438785.45 | E36: =E34 -> 482438.58 | F36: =F34 -> 528881.57 | G36: =G34 -> 578343.34 | H36: =H34 -> 631074.13 | I36: =I34+J35 -> 14104959
A37: Discounted Dividends | C37: =C34/(1+'P5 Cost of capital'!B39)^C9 -> 365927.3 | D37: =D34/(1+'P5 Cost of capital'!B39)^D9 -> 397991.34 | E37: =E34/(1+'P5 Cost of capital'!B39)^E9 -> 416748.58 | F37: =F34/(1+'P5 Cost of capital'!B39)^F9 -> 435112.17 | G37: =G34/(1+'P5 Cost of capital'!B39)^G9 -> 453147.14 | H37: =H34/(1+'P5 Cost of capital'!B39)^H9 -> 470917.23 | I37: =I34/(1+'P5 Cost of capital'!B39)^I9 -> 477339.56
A39: Equity based on Dividends | B39: =SUM(C37:I37)+(I36-SUM(C34:I34)) -> 13406731
A40: Stock price based on Dividends*1000 | B40: =(B39*1000)/'P3 Inputs'!B19 -> 1.2768315
A42: Market price | B42: ='P3 Inputs'!B18 -> 2.39
A44: Net Income | B44: ='P2 History'!X23 -> 1399000
A45: Market Capitalization | B45: =B42*'P3 Inputs'!B19 -> 25095000000
A46: PER | B46: =B42/(B44/'P3 Inputs'!B19) -> 17937.813
A48: Summary Stock valuation
A49: Stock price based on FCF | B49: =B29 -> 1.7827491
A50: Stock price based on Dividends | B50: =B40 -> 1.2768315
A51: Market price | B51: =B42 -> 2.39

Sheet P11 Conclusion
D1: Conclusion | G1: Points | H1: 20
A4: Capital Structure (5 points)
A6: Is your capital structure used for CAPEX financing is well structured ?
A7: Yes financing CAPEX equally with a bank loan, bonds, and equity is generally well structured because it diversifies funding sources and reduces dependence on one channel.
A9: Explain what would you do to make it more optimal, if possible ?
A10: To make that equal mix more optimal I would align the funding mix to capex timing, cash flow ability and cost of capital.
A12: Is your NWC optimal ?
A13: NWC is not optimal. Using projected values NWC is negative in every year and becomes more negative over time because of simplified total current assets=0
A15: What would you do to improve your NWC ?
A16: To improve NWC is to reduce the payables and current liabilities growth or increase current assets.
A18: Do you have cash gaps and how would you finance it ?
A19: Yes have potential cash gaps because NWC is negative and become more negative over time. To finance it use 1. Short term borrowing 2. Releasing cash from working capital 3. If gaps persist for mulitple years should switch to long term debt financing.
A22: Financial Statements Analysis (5 points)
... A55: I would suggest propose a mix of financial and non-financial incentives tied to the value in DCF, FCF, WACC, diciplined capital allocation.

Sheet P12 Instructor
B1: Instructor comments and Grade
A4: Pages | B4: Max Points | C4: Student Points
A5: P2 History'!A1 | B5: 5 | C5: ='P2 History'!F1 -> 5
A6: P4 Assets amortization'!A1 | B6: 5 | C6: ='P4 Assets amortization'!G1 -> 5
A7: P5 Cost of capital'!A1 | B7: 15 | C7: ='P5 Cost of capital'!G1 -> 15
A8: P6 P&L and BS Projection'!A1 | B8: 15 | C8: ='P6 P&L and BS Projection'!H1 -> 15
A9: P7 CF''s projection'!A1 | B9: 10 | C9: ='P7 CF''s projection'!H1 -> 10
A10: P8 Scenarios'!A1 | B10: 10 | C10: ='P8 Scenarios'!F1 -> 10
A11: P9 NWC'!A1 | B11: 5 | C11: ='P9 NWC'!H1 -> 5
A12: P10 Valuation'!A1 | B12: 15 | C12: ='P10 Valuation'!G1 -> 15
A13: P11 Conclusion'!A1 | B13: 20 | C13: ='P11 Conclusion'!H1 -> 20
A15: Total | B15: =SUM(B5:B14) -> 100 | C15: =SUM(C5:C14) -> 100
A17: Grade in % | B17: =C15% -> 1
A19: General Instructor Comments
A26: Grading scale:
